Traceback (most recent call last):
  File "/opt/hostedtoolcache/Python/3.11.13/x64/lib/python3.11/site-packages/jupyter_core/utils/__init__.py", line 154, in wrapped
    asyncio.get_running_loop()
RuntimeError: no running event loop

During handling of the above exception, another exception occurred:

Traceback (most recent call last):
  File "/opt/hostedtoolcache/Python/3.11.13/x64/lib/python3.11/site-packages/jupyter_cache/executors/utils.py", line 58, in single_nb_execution
    executenb(
  File "/opt/hostedtoolcache/Python/3.11.13/x64/lib/python3.11/site-packages/nbclient/client.py", line 1319, in execute
    return NotebookClient(nb=nb, resources=resources, km=km, **kwargs).execute()
           ^^^^^^^^^^^^^^^^^^^^^^^^^^^^^^^^^^^^^^^^^^^^^^^^^^^^^^^^^^^^^^^^^^^^^
  File "/opt/hostedtoolcache/Python/3.11.13/x64/lib/python3.11/site-packages/jupyter_core/utils/__init__.py", line 158, in wrapped
    return loop.run_until_complete(inner)
           ^^^^^^^^^^^^^^^^^^^^^^^^^^^^^^
  File "/opt/hostedtoolcache/Python/3.11.13/x64/lib/python3.11/asyncio/base_events.py", line 654, in run_until_complete
    return future.result()
           ^^^^^^^^^^^^^^^
  File "/opt/hostedtoolcache/Python/3.11.13/x64/lib/python3.11/site-packages/nbclient/client.py", line 709, in async_execute
    await self.async_execute_cell(
  File "/opt/hostedtoolcache/Python/3.11.13/x64/lib/python3.11/site-packages/nbclient/client.py", line 1062, in async_execute_cell
    await self._check_raise_for_error(cell, cell_index, exec_reply)
  File "/opt/hostedtoolcache/Python/3.11.13/x64/lib/python3.11/site-packages/nbclient/client.py", line 918, in _check_raise_for_error
    raise CellExecutionError.from_cell_and_msg(cell, exec_reply_content)
nbclient.exceptions.CellExecutionError: An error occurred while executing the following cell:
------------------
# Plot the GeoDataFrame by urbanizacion
f, ax = plt.subplots(1, 1, figsize=(10, 10))
gdf.plot(column='urbanizacion', ax=ax, legend=True, scheme='Quantiles', cmap='viridis', legend_kwds={'fmt':'{:.2f}'})
plt.title('Indice de urbanizacion por Municipio en Antioquia')
ax.set_axis_off()
plt.axis('equal')
plt.show()


------------------


[31m---------------------------------------------------------------------------[39m
[31mModuleNotFoundError[39m                       Traceback (most recent call last)
[36mFile [39m[32m/opt/hostedtoolcache/Python/3.11.13/x64/lib/python3.11/site-packages/geopandas/plotting.py:736[39m, in [36mplot_dataframe[39m[34m(df, column, cmap, color, ax, cax, categorical, legend, scheme, k, vmin, vmax, markersize, figsize, legend_kwds, categories, classification_kwds, missing_kwds, aspect, autolim, **style_kwds)[39m
[32m    735[39m [38;5;28;01mtry[39;00m:
[32m--> [39m[32m736[39m     [38;5;28;01mimport[39;00m[38;5;250m [39m[34;01mmapclassify[39;00m
[32m    738[39m [38;5;28;01mexcept[39;00m [38;5;167;01mImportError[39;00m:

[31mModuleNotFoundError[39m: No module named 'mapclassify'

During handling of the above exception, another exception occurred:

[31mImportError[39m                               Traceback (most recent call last)
[36mCell[39m[36m [39m[32mIn[3][39m[32m, line 3[39m
[32m      1[39m [38;5;66;03m# Plot the GeoDataFrame by urbanizacion[39;00m
[32m      2[39m f, ax = plt.subplots([32m1[39m, [32m1[39m, figsize=([32m10[39m, [32m10[39m))
[32m----> [39m[32m3[39m [43mgdf[49m[43m.[49m[43mplot[49m[43m([49m[43mcolumn[49m[43m=[49m[33;43m'[39;49m[33;43murbanizacion[39;49m[33;43m'[39;49m[43m,[49m[43m [49m[43max[49m[43m=[49m[43max[49m[43m,[49m[43m [49m[43mlegend[49m[43m=[49m[38;5;28;43;01mTrue[39;49;00m[43m,[49m[43m [49m[43mscheme[49m[43m=[49m[33;43m'[39;49m[33;43mQuantiles[39;49m[33;43m'[39;49m[43m,[49m[43m [49m[43mcmap[49m[43m=[49m[33;43m'[39;49m[33;43mviridis[39;49m[33;43m'[39;49m[43m,[49m[43m [49m[43mlegend_kwds[49m[43m=[49m[43m{[49m[33;43m'[39;49m[33;43mfmt[39;49m[33;43m'[39;49m[43m:[49m[33;43m'[39;49m[38;5;132;43;01m{:.2f}[39;49;00m[33;43m'[39;49m[43m}[49m[43m)[49m
[32m      4[39m plt.title([33m'[39m[33mIndice de urbanizacion por Municipio en Antioquia[39m[33m'[39m)
[32m      5[39m ax.set_axis_off()

[36mFile [39m[32m/opt/hostedtoolcache/Python/3.11.13/x64/lib/python3.11/site-packages/geopandas/plotting.py:962[39m, in [36mGeoplotAccessor.__call__[39m[34m(self, *args, **kwargs)[39m
[32m    960[39m kind = kwargs.pop([33m"[39m[33mkind[39m[33m"[39m, [33m"[39m[33mgeo[39m[33m"[39m)
[32m    961[39m [38;5;28;01mif[39;00m kind == [33m"[39m[33mgeo[39m[33m"[39m:
[32m--> [39m[32m962[39m     [38;5;28;01mreturn[39;00m [43mplot_dataframe[49m[43m([49m[43mdata[49m[43m,[49m[43m [49m[43m*[49m[43margs[49m[43m,[49m[43m [49m[43m*[49m[43m*[49m[43mkwargs[49m[43m)[49m
[32m    963[39m [38;5;28;01mif[39;00m kind [38;5;129;01min[39;00m [38;5;28mself[39m._pandas_kinds:
[32m    964[39m     [38;5;66;03m# Access pandas plots[39;00m
[32m    965[39m     [38;5;28;01mreturn[39;00m PlotAccessor(data)(kind=kind, **kwargs)

[36mFile [39m[32m/opt/hostedtoolcache/Python/3.11.13/x64/lib/python3.11/site-packages/geopandas/plotting.py:739[39m, in [36mplot_dataframe[39m[34m(df, column, cmap, color, ax, cax, categorical, legend, scheme, k, vmin, vmax, markersize, figsize, legend_kwds, categories, classification_kwds, missing_kwds, aspect, autolim, **style_kwds)[39m
[32m    736[39m     [38;5;28;01mimport[39;00m[38;5;250m [39m[34;01mmapclassify[39;00m
[32m    738[39m [38;5;28;01mexcept[39;00m [38;5;167;01mImportError[39;00m:
[32m--> [39m[32m739[39m     [38;5;28;01mraise[39;00m [38;5;167;01mImportError[39;00m(mc_err)
[32m    741[39m [38;5;28;01mif[39;00m classification_kwds [38;5;129;01mis[39;00m [38;5;28;01mNone[39;00m:
[32m    742[39m     classification_kwds = {}

[31mImportError[39m: The 'mapclassify' package is required to use the 'scheme' keyword.

